Workbook

Sheet Commission Summary
A1: Doral Office Binder Book - June 2026 Commission Statement
A2: Universal Insurance Brokers | Producer: Jorge | Statement period 06/01/2026 - 06/30/2026
A3: Commission taken from each carrier commission statement at the rate that carrier shows, matched by policy number. United Auto is booked at 10% as collected.
A5: Producer | B5: Customer Name | C5: Binder Status | D5: New / Renewal | E5: Line of Business | F5: Carrier | G5: Policy Number | H5: Eff. Date | I5: Term (mo) | J5: Binder Premium | K5: Carrier Statement Used | L5: # Txns | M5: Carrier Comm Rate | N5: Commissionable Premium | O5: Commission Earned | P5: Effective Rate | Q5: Notes | R5: key
A6: NEW BUSINESS
A7: Jorge | B7: MARLENE CASTILLO | C7: Active | D7: New Business | E7: Personal Auto | F7: Infinity | G7: 10268755201 | H7: 6/1/2026 | I7: 6 | J7: 1183 | K7: Kemper Auto Monthly Producer Stmt 06/2026 | L7: =COUNTIF('Transaction Detail'!$A$2:$A$385,$R7) -> 1 | M7: 0.1 | N7: =SUMIF('Transaction Detail'!$A$2:$A$385,$R7,'Transaction Detail'!$N$2:$N$385) -> 1183 | O7: =SUMIF('Transaction Detail'!$A$2:$A$385,$R7,'Transaction Detail'!$O$2:$O$385) -> 118.3 | P7: =IF(N7=0,"",O7/N7) -> 0.1 | R7: Infinity|10268755201
A8: Jorge | B8: LIONEL JOHNSON | C8: Active | D8: New Business | E8: Personal Auto | F8: Infinity | G8: 10268783901 | H8: 6/5/2026 | I8: 6 | J8: 944 | K8: Kemper Auto Monthly Producer Stmt 06/2026 | L8: =COUNTIF('Transaction Detail'!$A$2:$A$385,$R8) -> 1 | M8: 0.1 | N8: =SUMIF('Transaction Detail'!$A$2:$A$385,$R8,'Transaction Detail'!$N$2:$N$385) -> 934 | O8: =SUMIF('Transaction Detail'!$A$2:$A$385,$R8,'Transaction Detail'!$O$2:$O$385) -> 93.4 | P8: =IF(N8=0,"",O8/N8) -> 0.1 | R8: Infinity|10268783901
A9: Jorge | B9: LUIS A. ORTIZ | C9: Active | D9: New Business | E9: Personal Auto | F9: United Auto | G9: UAO 692181 | H9: 6/2/2026 | I9: 12 | J9: 1103.35 | K9: United Insurance Group Direct Billing Stmt 06/2026 | L9: =COUNTIF('Transaction Detail'!$A$2:$A$385,$R9) -> 2 | M9: 0.1 | N9: =SUMIF('Transaction Detail'!$A$2:$A$385,$R9,'Transaction Detail'!$N$2:$N$385) -> 163.6 | O9: =SUMIF('Transaction Detail'!$A$2:$A$385,$R9,'Transaction Detail'!$O$2:$O$385) -> 16.36 | P9: =IF(N9=0,"",O9/N9) -> 0.1 | Q9: United bills this policy direct and pays AS COLLECTED, so June earns commission only on the premium United collected in June - more follows in later months. | Booked at 10% as collected. United also paid a separate 3% promotional incentive of $4.90 on this policy - it is shown on the Transaction Detail tab but is deliberately EXCLUDED from this total. | | R9: United Auto|UAO692181
A10: Jorge | B10: GREGORIO QUIROZ | C10: Active | D10: New Business | E10: Personal Auto | F10: Progressive | G10: 875244202 | H10: 6/6/2026 | I10: 6 | J10: 1175 | K10: Progressive Detailed Statement 06/2026 | L10: =COUNTIF('Transaction Detail'!$A$2:$A$385,$R10) -> 1 | M10: 0.12 | N10: =SUMIF('Transaction Detail'!$A$2:$A$385,$R10,'Transaction Detail'!$N$2:$N$385) -> 1175 | O10: =SUMIF('Transaction Detail'!$A$2:$A$385,$R10,'Transaction Detail'!$O$2:$O$385) -> 141 | P10: =IF(N10=0,"",O10/N10) -> 0.12 | R10: Progressive|875244202
A11: Jorge | B11: JULIO RAMIREZ | C11: Active | D11: New Business | E11: Personal Auto | F11: Progressive | G11: 875310026 | H11: 6/8/2026 | I11: 6 | J11: 1935 | K11: Progressive Detailed Statement 06/2026 | L11: =COUNTIF('Transaction Detail'!$A$2:$A$385,$R11) -> 3 | M11: 0.14 | N11: =SUMIF('Transaction Detail'!$A$2:$A$385,$R11,'Transaction Detail'!$N$2:$N$385) -> 1413.29 | O11: =SUMIF('Transaction Detail'!$A$2:$A$385,$R11,'Transaction Detail'!$O$2:$O$385) -> 197.86 | P11: =IF(N11=0,"",O11/N11) -> 0.13999958 | Q11: Credit Endorsement -277.00 @ 14%; New Business 1,935.00 @ 14%; Credit Endorsement -244.71 @ 14% | R11: Progressive|875310026
A12: Jorge | B12: JAMIE JONES | C12: Active | D12: New Business | E12: Personal Auto | F12: Progressive | G12: 875520372 | H12: 6/12/2026 | I12: 6 | J12: 4319 | K12: Progressive Detailed Statement 06/2026 | L12: =COUNTIF('Transaction Detail'!$A$2:$A$385,$R12) -> 1 | M12: 0.1 | N12: =SUMIF('Transaction Detail'!$A$2:$A$385,$R12,'Transaction Detail'!$N$2:$N$385) -> 4319 | O12: =SUMIF('Transaction Detail'!$A$2:$A$385,$R12,'Transaction Detail'!$O$2:$O$385) -> 431.9 | P12: =IF(N12=0,"",O12/N12) -> 0.1 | R12: Progressive|875520372
A13: Jorge | B13: YUDMILA CADENAS | C13: Active | D13: New Business | E13: Personal Auto | F13: Progressive | G13: 875557253 | H13: 6/13/2026 | I13: 6 | J13: 1071 | K13: Progressive Detailed Statement 06/2026 | L13: =COUNTIF('Transaction Detail'!$A$2:$A$385,$R13) -> 1 | M13: 0.1 | N13: =SUMIF('Transaction Detail'!$A$2:$A$385,$R13,'Transaction Detail'!$N$2:$N$385) -> 1071 | O13: =SUMIF('Transaction Detail'!$A$2:$A$385,$R13,'Transaction Detail'!$O$2:$O$385) -> 107.1 | P13: =IF(N13=0,"",O13/N13) -> 0.1 | R13: Progressive|875557253
A14: Jorge | B14: JEAN H. GUSTAVE | C14: Active | D14: New Business | E14: Personal Auto | F14: United Auto | G14: UAO 694805 | H14: 6/13/2026 | I14: 12 | J14: 2840.35 | K14: United Insurance Group Direct Billing Stmt 06/2026 | L14: =COUNTIF('Transaction Detail'!$A$2:$A$385,$R14) -> 2 | M14: 0.1 | N14: =SUMIF('Transaction Detail'!$A$2:$A$385,$R14,'Transaction Detail'!$N$2:$N$385) -> 2797 | O14: =SUMIF('Transaction Detail'!$A$2:$A$385,$R14,'Transaction Detail'!$O$2:$O$385) -> 279.7 | P14: =IF(N14=0,"",O14/N14) -> 0.1 | Q14: Booked at 10% as collected. United also paid a separate 3% promotional incentive of $83.91 on this policy - it is shown on the Transaction Detail tab but is deliberately EXCLUDED from this total. | | R14: United Auto|UAO694805
A15: Jorge | B15: YOANNY ALONSO M. | C15: Active | D15: New Business | E15: Personal Auto | F15: Progressive | G15: 875569393 | H15: 6/13/2026 | I15: 6 | J15: 1568 | K15: Progressive Detailed Statement 06/2026 | L15: =COUNTIF('Transaction Detail'!$A$2:$A$385,$R15) -> 1 | M15: 0.1 | N15: =SUMIF('Transaction Detail'!$A$2:$A$385,$R15,'Transaction Detail'!$N$2:$N$385) -> 1568 | O15: =SUMIF('Transaction Detail'!$A$2:$A$385,$R15,'Transaction Detail'!$O$2:$O$385) -> 156.8 | P15: =IF(N15=0,"",O15/N15) -> 0.1 | R15: Progressive|875569393
A16: Jorge | B16: YADIER CORDERO G. | C16: Active | D16: New Business | E16: Personal Auto | F16: United Auto | G16: UAO 695126 | H16: 6/15/2026 | I16: 12 | J16: 2268 | K16: United Insurance Group Direct Billing Stmt 06/2026 | L16: =COUNTIF('Transaction Detail'!$A$2:$A$385,$R16) -> 4 | M16: 0.1 | N16: =SUMIF('Transaction Detail'!$A$2:$A$385,$R16,'Transaction Detail'!$N$2:$N$385) -> 2485 | O16: =SUMIF('Transaction Detail'!$A$2:$A$385,$R16,'Transaction Detail'!$O$2:$O$385) -> 248.5 | P16: =IF(N16=0,"",O16/N16) -> 0.1 | Q16: Booked at 10% as collected. United also paid a separate 3% promotional incentive of $74.55 on this policy - it is shown on the Transaction Detail tab but is deliberately EXCLUDED from this total. | New Business 2,233.00 @ 10%; Endorsement 252.00 @ 10% | R16: United Auto|UAO695126
A17: Jorge | B17: STEPHANIE VAZQUEZ | C17: Active | D17: New Business | E17: Personal Auto | F17: United Auto | G17: UAO 695998 | H17: 6/19/2026 | I17: 12 | J17: 1122.35 | K17: United Insurance Group Direct Billing Stmt 06/2026 | L17: =COUNTIF('Transaction Detail'!$A$2:$A$385,$R17) -> 2 | M17: 0.1 | N17: =SUMIF('Transaction Detail'!$A$2:$A$385,$R17,'Transaction Detail'!$N$2:$N$385) -> 1079 | O17: =SUMIF('Transaction Detail'!$A$2:$A$385,$R17,'Transaction Detail'!$O$2:$O$385) -> 107.9 | P17: =IF(N17=0,"",O17/N17) -> 0.1 | Q17: Booked at 10% as collected. United also paid a separate 3% promotional incentive of $32.37 on this policy - it is shown on the Transaction Detail tab but is deliberately EXCLUDED from this total. | | R17: United Auto|UAO695998
A18: Jorge | B18: TAURUS L. PRESSLEY | C18: Active | D18: New Business | E18: Personal Auto | F18: Infinity | G18: 10270293001 | H18: 6/20/2026 | I18: 6 | J18: 820 | K18: Kemper Auto Monthly Producer Stmt 06/2026 | L18: =COUNTIF('Transaction Detail'!$A$2:$A$385,$R18) -> 1 | M18: 0.1 | N18: =SUMIF('Transaction Detail'!$A$2:$A$385,$R18,'Transaction Detail'!$N$2:$N$385) -> 810 | O18: =SUMIF('Transaction Detail'!$A$2:$A$385,$R18,'Transaction Detail'!$O$2:$O$385) -> 81 | P18: =IF(N18=0,"",O18/N18) -> 0.1 | R18: Infinity|10270293001
A19: Jorge | B19: ANTHONY PATTERSON | C19: Active | D19: New Business | E19: Personal Auto | F19: Progressive | G19: 875889820 | H19: 6/20/2026 | I19: 6 | J19: 1760 | K19: Progressive Detailed Statement 06/2026 | L19: =COUNTIF('Transaction Detail'!$A$2:$A$385,$R19) -> 2 | M19: 0.1 | N19: =SUMIF('Transaction Detail'!$A$2:$A$385,$R19,'Transaction Detail'!$N$2:$N$385) -> 1674 | O19: =SUMIF('Transaction Detail'!$A$2:$A$385,$R19,'Transaction Detail'!$O$2:$O$385) -> 167.4 | P19: =IF(N19=0,"",O19/N19) -> 0.1 | Q19: Credit Endorsement -86.00 @ 10%; New Business 1,760.00 @ 10% | R19: Progressive|875889820
A20: Jorge | B20: FELIPE GONZALEZ | C20: Active | D20: New Business | E20: Personal Auto | F20: Infinity | G20: 10270429601 | H20: 6/23/2026 | I20: 6 | J20: 1460 | K20: Kemper Auto Monthly Producer Stmt 06/2026 | L20: =COUNTIF('Transaction Detail'!$A$2:$A$385,$R20) -> 1 | M20: 0.1 | N20: =SUMIF('Transaction Detail'!$A$2:$A$385,$R20,'Transaction Detail'!$N$2:$N$385) -> 1450 | O20: =SUMIF('Transaction Detail'!$A$2:$A$385,$R20,'Transaction Detail'!$O$2:$O$385) -> 145 | P20: =IF(N20=0,"",O20/N20) -> 0.1 | R20: Infinity|10270429601
A21: Jorge | B21: CHRISTINA COSME | C21: Active | D21: New Business | E21: Personal Auto | F21: Progressive | G21: 876013327 | H21: 6/23/2026 | I21: 6 | J21: 1770 | K21: Progressive Detailed Statement 06/2026 | L21: =COUNTIF('Transaction Detail'!$A$2:$A$385,$R21) -> 1 | M21: 0.12 | N21: =SUMIF('Transaction Detail'!$A$2:$A$385,$R21,'Transaction Detail'!$N$2:$N$385) -> 1770 | O21: =SUMIF('Transaction Detail'!$A$2:$A$385,$R21,'Transaction Detail'!$O$2:$O$385) -> 212.4 | P21: =IF(N21=0,"",O21/N21) -> 0.12 | R21: Progressive|876013327
A22: Jorge | B22: CARLOS TABOADA | C22: Active | D22: New Business | E22: Personal Auto | F22: Progressive | G22: 876150583 | H22: 6/26/2026 | I22: 6 | J22: 370 | K22: Progressive Detailed Statement 06/2026 | L22: =COUNTIF('Transaction Detail'!$A$2:$A$385,$R22) -> 1 | M22: 0.1 | N22: =SUMIF('Transaction Detail'!$A$2:$A$385,$R22,'Transaction Detail'!$N$2:$N$385) -> 370 | O22: =SUMIF('Transaction Detail'!$A$2:$A$385,$R22,'Transaction Detail'!$O$2:$O$385) -> 37 | P22: =IF(N22=0,"",O22/N22) -> 0.1 | R22: Progressive|876150583
A23: Jorge | B23: MICHAEL D. HOWARD | C23: Active | D23: New Business | E23: Personal Auto | F23: United Auto | G23: UAO 697725 | H23: 6/27/2026 | I23: 6 | J23: 1406.35 | K23: United Insurance Group Direct Billing Stmt 06/2026 | L23: =COUNTIF('Transaction Detail'!$A$2:$A$385,$R23) -> 2 | M23: 0.1 | N23: =SUMIF('Transaction Detail'!$A$2:$A$385,$R23,'Transaction Detail'!$N$2:$N$385) -> 1373 | O23: =SUMIF('Transaction Detail'!$A$2:$A$385,$R23,'Transaction Detail'!$O$2:$O$385) -> 137.3 | P23: =IF(N23=0,"",O23/N23) -> 0.1 | Q23: Booked at 10% as collected. United also paid a separate 3% promotional incentive of $41.19 on this policy - it is shown on the Transaction Detail tab but is deliberately EXCLUDED from this total. | | R23: United Auto|UAO697725
A24: Jorge | B24: BRIANNA IRISH | C24: Active | D24: New Business | E24: Personal Auto | F24: Progressive | G24: 876186100 | H24: 6/26/2026 | I24: 6 | J24: 1994 | K24: Progressive Detailed Statement 06/2026 | L24: =COUNTIF('Transaction Detail'!$A$2:$A$385,$R24) -> 1 | M24: 0.1 | N24: =SUMIF('Transaction Detail'!$A$2:$A$385,$R24,'Transaction Detail'!$N$2:$N$385) -> 1994 | O24: =SUMIF('Transaction Detail'!$A$2:$A$385,$R24,'Transaction Detail'!$O$2:$O$385) -> 199.4 | P24: =IF(N24=0,"",O24/N24) -> 0.1 | R24: Progressive|876186100
B25: NEW BUSINESS SUBTOTAL | J25: =SUM(J7:J24) -> 29109.4 | N25: =SUM(N7:N24) -> 27628.89 | O25: =SUM(O7:O24) -> 2878.32 | P25: =IF(N25=0,"",O25/N25) -> 0.10417791
A27: RENEWALS
A28: Jorge | B28: AMARILLYS GONZALEZ | C28: Renewed | D28: Renewal | E28: Personal Auto | F28: Progressive | G28: 970306264 | H28: 6/1/2026 | I28: 6 | J28: 940 | K28: Progressive Detailed Statement 06/2026 | L28: =COUNTIF('Transaction Detail'!$A$2:$A$385,$R28) -> 0 | N28: =SUMIF('Transaction Detail'!$A$2:$A$385,$R28,'Transaction Detail'!$N$2:$N$385) -> 0 | O28: =SUMIF('Transaction Detail'!$A$2:$A$385,$R28,'Transaction Detail'!$O$2:$O$385) -> 0 | P28: =IF(N28=0,"",O28/N28) | Q28: Policy not found on the June 2026 Progressive statement - commission likely paid in a different statement period. | R28: Progressive|970306264
A29: Jorge | B29: BRUDYS GARCIA | C29: Renewed | D29: Renewal | E29: Personal Auto | F29: Progressive | G29: 990100610 | H29: 6/2/2026 | I29: 6 | J29: 1217 | K29: Progressive Detailed Statement 06/2026 | L29: =COUNTIF('Transaction Detail'!$A$2:$A$385,$R29) -> 0 | N29: =SUMIF('Transaction Detail'!$A$2:$A$385,$R29,'Transaction Detail'!$N$2:$N$385) -> 0 | O29: =SUMIF('Transaction Detail'!$A$2:$A$385,$R29,'Transaction Detail'!$O$2:$O$385) -> 0 | P29: =IF(N29=0,"",O29/N29) | Q29: Policy not found on the June 2026 Progressive statement - commission likely paid in a different statement period. | R29: Progressive|990100610
A30: Jorge | B30: YOSVANY LARRALDE | C30: Renewed | D30: Renewal | E30: Boat | F30: Progressive | G30: 982064065 | H30: 6/3/2026 | I30: 12 | J30: 719.12 | K30: Progressive Detailed Statement 06/2026 | L30: =COUNTIF('Transaction Detail'!$A$2:$A$385,$R30) -> 0 | N30: =SUMIF('Transaction Detail'!$A$2:$A$385,$R30,'Transaction Detail'!$N$2:$N$385) -> 0 | O30: =SUMIF('Transaction Detail'!$A$2:$A$385,$R30,'Transaction Detail'!$O$2:$O$385) -> 0 | P30: =IF(N30=0,"",O30/N30) | Q30: Policy not found on the June 2026 Progressive statement - commission likely paid in a different statement period. | R30: Progressive|982064065
A31: Jorge | B31: ANA G CASTANO | C31: Renewed | D31: Renewal | E31: Personal Auto | F31: Progressive | G31: 866496112 | H31: 6/3/2026 | I31: 6 | J31: 1023 | K31: Progressive Detailed Statement 06/2026 | L31: =COUNTIF('Transaction Detail'!$A$2:$A$385,$R31) -> 0 | N31: =SUMIF('Transaction Detail'!$A$2:$A$385,$R31,'Transaction Detail'!$N$2:$N$385) -> 0 | O31: =SUMIF('Transaction Detail'!$A$2:$A$385,$R31,'Transaction Detail'!$O$2:$O$385) -> 0 | P31: =IF(N31=0,"",O31/N31) | Q31: Policy not found on the June 2026 Progressive statement - commission likely paid in a different statement period. | R31: Progressive|866496112
A32: Jorge | B32: MANUEL MARTINEZ | C32: Renewed | D32: Renewal | E32: Personal Auto | F32: Progressive | G32: 990228513 | H32: 6/5/2026 | I32: 6 | J32: 3495 | K32: Progressive Detailed Statement 06/2026 | L32: =COUNTIF('Transaction Detail'!$A$2:$A$385,$R32) -> 0 | N32: =SUMIF('Transaction Detail'!$A$2:$A$385,$R32,'Transaction Detail'!$N$2:$N$385) -> 0 | O32: =SUMIF('Transaction Detail'!$A$2:$A$385,$R32,'Transaction Detail'!$O$2:$O$385) -> 0 | P32: =IF(N32=0,"",O32/N32) | Q32: Policy not found on the June 2026 Progressive statement - commission likely paid in a different statement period. | R32: Progressive|990228513
A33: Jorge | B33: NIEVES ABREU | C33: Renewed | D33: Renewal | E33: Personal Auto | F33: Progressive | G33: 866656050 | H33: 6/6/2026 | I33: 6 | J33: 2276 | K33: Progressive Detailed Statement 06/2026 | L33: =COUNTIF('Transaction Detail'!$A$2:$A$385,$R33) -> 1 | M33: 0.1 | N33: =SUMIF('Transaction Detail'!$A$2:$A$385,$R33,'Transaction Detail'!$N$2:$N$385) -> 2276 | O33: =SUMIF('Transaction Detail'!$A$2:$A$385,$R33,'Transaction Detail'!$O$2:$O$385) -> 227.6 | P33: =IF(N33=0,"",O33/N33) -> 0.1 | R33: Progressive|866656050
A34: Jorge | B34: IBET COLLADO | C34: Renewed | D34: Renewal | E34: Personal Auto | F34: Progressive | G34: 982208807 | H34: 6/6/2026 | I34: 6 | J34: 854 | K34: Progressive Detailed Statement 06/2026 | L34: =COUNTIF('Transaction Detail'!$A$2:$A$385,$R34) -> 1 | M34: 0.1 | N34: =SUMIF('Transaction Detail'!$A$2:$A$385,$R34,'Transaction Detail'!$N$2:$N$385) -> 854 | O34: =SUMIF('Transaction Detail'!$A$2:$A$385,$R34,'Transaction Detail'!$O$2:$O$385) -> 85.4 | P34: =IF(N34=0,"",O34/N34) -> 0.1 | R34: Progressive|982208807
A35: Jorge | B35: ALEJANDRO COLLADO | C35: Renewed | D35: Renewal | E35: Personal Auto | F35: Progressive | G35: 48745204 | H35: 6/7/2026 | I35: 6 | J35: 1956 | K35: Progressive Detailed Statement 06/2026 | L35: =COUNTIF('Transaction Detail'!$A$2:$A$385,$R35) -> 2 | M35: 0.1 | N35: =SUMIF('Transaction Detail'!$A$2:$A$385,$R35,'Transaction Detail'!$N$2:$N$385) -> 1355.77 | O35: =SUMIF('Transaction Detail'!$A$2:$A$385,$R35,'Transaction Detail'!$O$2:$O$385) -> 135.58 | P35: =IF(N35=0,"",O35/N35) -> 0.10000221 | Q35: Renewal 1,956.00 @ 10%; Credit Endorsement -600.23 @ 10% | R35: Progressive|48745204
A36: Jorge | B36: MANUELA GOMEZ OROZCO | C36: Renewed | D36: Renewal | E36: Personal Auto | F36: Progressive | G36: 866615155 | H36: 6/8/2026 | I36: 6 | J36: 2305 | K36: Progressive Detailed Statement 06/2026 | L36: =COUNTIF('Transaction Detail'!$A$2:$A$385,$R36) -> 1 | M36: 0.1 | N36: =SUMIF('Transaction Detail'!$A$2:$A$385,$R36,'Transaction Detail'!$N$2:$N$385) -> 2305 | O36: =SUMIF('Transaction Detail'!$A$2:$A$385,$R36,'Transaction Detail'!$O$2:$O$385) -> 230.5 | P36: =IF(N36=0,"",O36/N36) -> 0.1 | R36: Progressive|866615155
A37: Jorge | B37: REYSEL CASTILLO | C37: Renewed | D37: Renewal | E37: Boat | F37: Progressive | G37: 970570633 | H37: 6/9/2026 | I37: 12 | J37: 688.82 | K37: Progressive Detailed Statement 06/2026 | L37: =COUNTIF('Transaction Detail'!$A$2:$A$385,$R37) -> 0 | N37: =SUMIF('Transaction Detail'!$A$2:$A$385,$R37,'Transaction Detail'!$N$2:$N$385) -> 0 | O37: =SUMIF('Transaction Detail'!$A$2:$A$385,$R37,'Transaction Detail'!$O$2:$O$385) -> 0 | P37: =IF(N37=0,"",O37/N37) | Q37: Policy not found on the June 2026 Progressive statement - commission likely paid in a different statement period. | R37: Progressive|970570633
A38: Jorge | B38: ERIC CRUZ | C38: Renewed | D38: Renewal | E38: Personal Auto | F38: Progressive | G38: 998651589 | H38: 6/10/2026 | I38: 6 | J38: 2194 | K38: Progressive Detailed Statement 06/2026 | L38: =COUNTIF('Transaction Detail'!$A$2:$A$385,$R38) -> 1 | M38: 0.1 | N38: =SUMIF('Transaction Detail'!$A$2:$A$385,$R38,'Transaction Detail'!$N$2:$N$385) -> 2194 | O38: =SUMIF('Transaction Detail'!$A$2:$A$385,$R38,'Transaction Detail'!$O$2:$O$385) -> 219.4 | P38: =IF(N38=0,"",O38/N38) -> 0.1 | R38: Progressive|998651589
A39: Jorge | B39: JORGE A AGUIRRE MARIN | C39: Renewed | D39: Renewal | E39: Personal Auto | F39: Progressive | G39: 944684751 | H39: 6/11/2025 | I39: 6 | J39: 1906 | K39: Progressive Detailed Statement 06/2026 | L39: =COUNTIF('Transaction Detail'!$A$2:$A$385,$R39) -> 1 | M39: 0.1 | N39: =SUMIF('Transaction Detail'!$A$2:$A$385,$R39,'Transaction Detail'!$N$2:$N$385) -> 1906 | O39: =SUMIF('Transaction Detail'!$A$2:$A$385,$R39,'Transaction Detail'!$O$2:$O$385) -> 190.6 | P39: =IF(N39=0,"",O39/N39) -> 0.1 | R39: Progressive|944684751
A40: Jorge | B40: NATHAN R WALTERS | C40: Renewed | D40: Renewal | E40: Personal Auto | F40: Progressive | G40: 990565433 | H40: 6/13/2026 | I40: 6 | J40: 2083 | K40: Progressive Detailed Statement 06/2026 | L40: =COUNTIF('Transaction Detail'!$A$2:$A$385,$R40) -> 1 | M40: 0.1 | N40: =SUMIF('Transaction Detail'!$A$2:$A$385,$R40,'Transaction Detail'!$N$2:$N$385) -> 2083 | O40: =SUMIF('Transaction Detail'!$A$2:$A$385,$R40,'Transaction Detail'!$O$2:$O$385) -> 208.3 | P40: =IF(N40=0,"",O40/N40) -> 0.1 | R40: Progressive|990565433
A41: Jorge | B41: GUSTAVO F ALFONSO | C41: Renewed | D41: Renewal | E41: Personal Auto | F41: Progressive | G41: 975650843 | H41: 6/13/2026 | I41: 6 | J41: 1205 | K41: Progressive Detailed Statement 06/2026 | L41: =COUNTIF('Transaction Detail'!$A$2:$A$385,$R41) -> 1 | M41: 0.1 | N41: =SUMIF('Transaction Detail'!$A$2:$A$385,$R41,'Transaction Detail'!$N$2:$N$385) -> 1205 | O41: =SUMIF('Transaction Detail'!$A$2:$A$385,$R41,'Transaction Detail'!$O$2:$O$385) -> 120.5 | P41: =IF(N41=0,"",O41/N41) -> 0.1 | R41: Progressive|975650843
A42: Jorge | B42: CARMELO QUINTO | C42: Renewed | D42: Renewal | E42: Personal Auto | F42: Progressive | G42: 970707982 | H42: 6/14/2026 | I42: 6 | J42: 1278 | K42: Progressive Detailed Statement 06/2026 | L42: =COUNTIF('Transaction Detail'!$A$2:$A$385,$R42) -> 1 | M42: 0.1 | N42: =SUMIF('Transaction Detail'!$A$2:$A$385,$R42,'Transaction Detail'!$N$2:$N$385) -> 1278 | O42: =SUMIF('Transaction Detail'!$A$2:$A$385,$R42,'Transaction Detail'!$O$2:$O$385) -> 127.8 | P42: =IF(N42=0,"",O42/N42) -> 0.1 | R42: Progressive|970707982
...

Sheet Transaction Detail
A1: Match Key | B1: Carrier | C1: Commission Statement | D1: Statement Policy # | E1: Insured Name (per statement) | F1: Transaction Type | G1: Transaction Date | H1: Written / Gross Premium | I1: Commissionable Basis | J1: Carrier Comm Rate | K1: Commission per Statement | L1: Check: Basis x Rate | M1: Diff | N1: Premium Counted in Summary | O1: Commission Counted in Summary | P1: In Doral Binder Book? | Q1: Binder Customer Name
A2: Progressive|48745204 | B2: Progressive | C2: Progressive Detailed Statement 06/2026 | D2: 48745204 | E2: COLLADO A. | F2: Renewal | G2: 06/07/2026 | H2: 1956 | I2: 1956 | J2: 0.1 | K2: 195.6 | L2: =ROUND(I2*J2,2) -> 195.6 | M2: =K2-L2 -> 0 | N2: =IF(F2="Promotional Incentive",0,I2) -> 1956 | O2: =IF(F2="Promotional Incentive",0,K2) -> 195.6 | P2: YES | Q2: ALEJANDRO COLLADO
A3: Progressive|48745204 | B3: Progressive | C3: Progressive Detailed Statement 06/2026 | D3: 48745204 | E3: COLLADO A. | F3: Credit Endorsement | G3: 06/10/2026 | H3: -600.23 | I3: -600.23 | J3: 0.1 | K3: -60.02 | L3: =ROUND(I3*J3,2) -> -60.02 | M3: =K3-L3 -> 0 | N3: =IF(F3="Promotional Incentive",0,I3) -> -600.23 | O3: =IF(F3="Promotional Incentive",0,K3) -> -60.02 | P3: YES | Q3: ALEJANDRO COLLADO
A4: Progressive|866615155 | B4: Progressive | C4: Progressive Detailed Statement 06/2026 | D4: 866615155 | E4: GOMEZ OROZCO M. | F4: Renewal | G4: 06/08/2026 | H4: 2305 | I4: 2305 | J4: 0.1 | K4: 230.5 | L4: =ROUND(I4*J4,2) -> 230.5 | M4: =K4-L4 -> 0 | N4: =IF(F4="Promotional Incentive",0,I4) -> 2305 | O4: =IF(F4="Promotional Incentive",0,K4) -> 230.5 | P4: YES | Q4: MANUELA GOMEZ OROZCO
A5: Progressive|866656050 | B5: Progressive | C5: Progressive Detailed Statement 06/2026 | D5: 866656050 | E5: ABREU N. | F5: Renewal | G5: 06/06/2026 | H5: 2276 | I5: 2276 | J5: 0.1 | K5: 227.6 | L5: =ROUND(I5*J5,2) -> 227.6 | M5: =K5-L5 -> 0 | N5: =IF(F5="Promotional Incentive",0,I5) -> 2276 | O5: =IF(F5="Promotional Incentive",0,K5) -> 227.6 | P5: YES | Q5: NIEVES ABREU
A6: Progressive|866980392 | B6: Progressive | C6: Progressive Detailed Statement 06/2026 | D6: 866980392 | E6: TORRES ARTOL E. | F6: Renewal | G6: 06/15/2026 | H6: 539 | I6: 539 | J6: 0.1 | K6: 53.9 | L6: =ROUND(I6*J6,2) -> 53.9 | M6: =K6-L6 -> 0 | N6: =IF(F6="Promotional Incentive",0,I6) -> 539 | O6: =IF(F6="Promotional Incentive",0,K6) -> 53.9 | P6: YES | Q6: ERNESTO TORRES ARTOLA
A7: Progressive|867024300 | B7: Progressive | C7: Progressive Detailed Statement 06/2026 | D7: 867024300 | E7: SANTANA GUER N. | F7: Renewal | G7: 06/16/2026 | H7: 945 | I7: 945 | J7: 0.1 | K7: 94.5 | L7: =ROUND(I7*J7,2) -> 94.5 | M7: =K7-L7 -> 0 | N7: =IF(F7="Promotional Incentive",0,I7) -> 945 | O7: =IF(F7="Promotional Incentive",0,K7) -> 94.5 | P7: YES | Q7: NOEMI SANTANA GUERRA
A8: Progressive|867210259 | B8: Progressive | C8: Progressive Detailed Statement 06/2026 | D8: 867210259 | E8: LAMOTHE J. | F8: Renewal | G8: 06/20/2026 | H8: 947 | I8: 947 | J8: 0.1 | K8: 94.7 | L8: =ROUND(I8*J8,2) -> 94.7 | M8: =K8-L8 -> 0 | N8: =IF(F8="Promotional Incentive",0,I8) -> 947 | O8: =IF(F8="Promotional Incentive",0,K8) -> 94.7 | P8: YES | Q8: JEAN R LAMOTHE
A9: Progressive|875244202 | B9: Progressive | C9: Progressive Detailed Statement 06/2026 | D9: 875244202 | E9: QUIROZ G. | F9: New Business | G9: 06/06/2026 | H9: 1175 | I9: 1175 | J9: 0.12 | K9: 141 | L9: =ROUND(I9*J9,2) -> 141 | M9: =K9-L9 -> 0 | N9: =IF(F9="Promotional Incentive",0,I9) -> 1175 | O9: =IF(F9="Promotional Incentive",0,K9) -> 141 | P9: YES | Q9: GREGORIO QUIROZ
A10: Progressive|875310026 | B10: Progressive | C10: Progressive Detailed Statement 06/2026 | D10: 875310026 | E10: RAMIREZ J. | F10: Credit Endorsement | G10: 06/08/2026 | H10: -277 | I10: -277 | J10: 0.14 | K10: -38.78 | L10: =ROUND(I10*J10,2) -> -38.78 | M10: =K10-L10 -> 0 | N10: =IF(F10="Promotional Incentive",0,I10) -> -277 | O10: =IF(F10="Promotional Incentive",0,K10) -> -38.78 | P10: YES | Q10: JULIO RAMIREZ
A11: Progressive|875310026 | B11: Progressive | C11: Progressive Detailed Statement 06/2026 | D11: 875310026 | E11: RAMIREZ J. | F11: New Business | G11: 06/08/2026 | H11: 1935 | I11: 1935 | J11: 0.14 | K11: 270.9 | L11: =ROUND(I11*J11,2) -> 270.9 | M11: =K11-L11 -> 0 | N11: =IF(F11="Promotional Incentive",0,I11) -> 1935 | O11: =IF(F11="Promotional Incentive",0,K11) -> 270.9 | P11: YES | Q11: JULIO RAMIREZ
A12: Progressive|875310026 | B12: Progressive | C12: Progressive Detailed Statement 06/2026 | D12: 875310026 | E12: RAMIREZ J. | F12: Credit Endorsement | G12: 06/16/2026 | H12: -244.71 | I12: -244.71 | J12: 0.14 | K12: -34.26 | L12: =ROUND(I12*J12,2) -> -34.26 | M12: =K12-L12 -> 0 | N12: =IF(F12="Promotional Incentive",0,I12) -> -244.71 | O12: =IF(F12="Promotional Incentive",0,K12) -> -34.26 | P12: YES | Q12: JULIO RAMIREZ
A13: Progressive|875520372 | B13: Progressive | C13: Progressive Detailed Statement 06/2026 | D13: 875520372 | E13: JONES J. | F13: New Business | G13: 06/12/2026 | H13: 4319 | I13: 4319 | J13: 0.1 | K13: 431.9 | L13: =ROUND(I13*J13,2) -> 431.9 | M13: =K13-L13 -> 0 | N13: =IF(F13="Promotional Incentive",0,I13) -> 4319 | O13: =IF(F13="Promotional Incentive",0,K13) -> 431.9 | P13: YES | Q13: JAMIE JONES
... A35: Progressive|999181480 | B35: Progressive | C35: Progressive Detailed Statement 06/2026 | D35: 999181480 | E35: PEREZ J. | F35: Renewal | G35: 06/21/2026 | H35: 619 | I35: 619 | J35: 0.1 | K35: 61.9 | L35: =ROUND(I35*J35,2) -> 61.9 | M35: =K35-L35 -> 0 | N35: =IF(F35="Promotional Incentive",0,I35) -> 619 | O35: =IF(F35="Promotional Incentive",0,K35) -> 61.9 | P35: YES | Q35: JUAN N PEREZ
A36: Progressive|1209267 | B36: Progressive | C36: Progressive Detailed Statement 06/2026 | D36: 01209267 | E36: EXPERT REMO . | F36: Endorsement | G36: 06/26/2026 | H36: 1717 | I36: 1717 | J36: 0.1 | K36: 171.7 | L36: =ROUND(I36*J36,2) -> 171.7 | M36: =K36-L36 -> 0 | N36: =IF(F36="Promotional Incentive",0,I36) -> 1717 | O36: =IF(F36="Promotional Incentive",0,K36) -> 171.7 | P36: No
A37: Progressive|862046493 | B37: Progressive | C37: Progressive Detailed Statement 06/2026 | D37: 862046493 | E37: BERMUDEZ V. | F37: Credit Endorsement | G37: 06/06/2026 | H37: -120.66 | I37: -120.66 | J37: 0.1 | K37: -12.07 | L37: =ROUND(I37*J37,2) -> -12.07 | M37: =K37-L37 -> 0 | N37: =IF(F37="Promotional Incentive",0,I37) -> -120.66 | O37: =IF(F37="Promotional Incentive",0,K37) -> -12.07 | P37: No
A38: Progressive|862085078 | B38: Progressive | C38: Progressive Detailed Statement 06/2026 | D38: 862085078 | E38: MOLINA LOZAN I. | F38: Endorsement | G38: 06/06/2026 | H38: 299.97 | I38: 299.97 | J38: 0.1 | K38: 30 | L38: =ROUND(I38*J38,2) -> 30 | M38: =K38-L38 -> 0 | N38: =IF(F38="Promotional Incentive",0,I38) -> 299.97 | O38: =IF(F38="Promotional Incentive",0,K38) -> 30 | P38: No
A39: Progressive|864173304 | B39: Progressive | C39: Progressive Detailed Statement 06/2026 | D39: 864173304 | E39: ATIAS O. | F39: Endorsement | G39: 06/07/2026 | H39: 213.57 | I39: 213.57 | J39: 0.1 | K39: 21.36 | L39: =ROUND(I39*J39,2) -> 21.36 | M39: =K39-L39 -> 0 | N39: =IF(F39="Promotional Incentive",0,I39) -> 213.57 | O39: =IF(F39="Promotional Incentive",0,K39) -> 21.36 | P39: No
A40: Progressive|866455034 | B40: Progressive | C40: Progressive Detailed Statement 06/2026 | D40: 866455034 | E40: BRAVO FLORES A. | F40: Renewal | G40: 06/16/2026 | H40: 1135 | I40: 1135 | J40: 0.1 | K40: 113.5 | L40: =ROUND(I40*J40,2) -> 113.5 | M40: =K40-L40 -> 0 | N40: =IF(F40="Promotional Incentive",0,I40) -> 1135 | O40: =IF(F40="Promotional Incentive",0,K40) -> 113.5 | P40: No
A41: Progressive|866544932 | B41: Progressive | C41: Progressive Detailed Statement 06/2026 | D41: 866544932 | E41: ZALDIVAR V. | F41: Renewal | G41: 06/18/2026 | H41: 1103 | I41: 1103 | J41: 0.1 | K41: 110.3 | L41: =ROUND(I41*J41,2) -> 110.3 | M41: =K41-L41 -> 0 | N41: =IF(F41="Promotional Incentive",0,I41) -> 1103 | O41: =IF(F41="Promotional Incentive",0,K41) -> 110.3 | P41: No
A42: Progressive|866921710 | B42: Progressive | C42: Progressive Detailed Statement 06/2026 | D42: 866921710 | E42: PEREZ H. | F42: Renewal | G42: 06/13/2026 | H42: 534 | I42: 534 | J42: 0.1 | K42: 53.4 | L42: =ROUND(I42*J42,2) -> 53.4 | M42: =K42-L42 -> 0 | N42: =IF(F42="Promotional Incentive",0,I42) -> 534 | O42: =IF(F42="Promotional Incentive",0,K42) -> 53.4 | P42: No
A43: Progressive|866944927 | B43: Progressive | C43: Progressive Detailed Statement 06/2026 | D43: 866944927 | E43: DA SILVA D. | F43: Renewal | G43: 06/14/2026 | H43: 1554 | I43: 1554 | J43: 0.1 | K43: 155.4 | L43: =ROUND(I43*J43,2) -> 155.4 | M43: =K43-L43 -> 0 | N43: =IF(F43="Promotional Incentive",0,I43) -> 1554 | O43: =IF(F43="Promotional Incentive",0,K43) -> 155.4 | P43: No
A44: Progressive|866989409 | B44: Progressive | C44: Progressive Detailed Statement 06/2026 | D44: 866989409 | E44: ACOBO M. | F44: Renewal | G44: 06/15/2026 | H44: 1486 | I44: 1486 | J44: 0.1 | K44: 148.6 | L44: =ROUND(I44*J44,2) -> 148.6 | M44: =K44-L44 -> 0 | N44: =IF(F44="Promotional Incentive",0,I44) -> 1486 | O44: =IF(F44="Promotional Incentive",0,K44) -> 148.6 | P44: No
A45: Progressive|867082146 | B45: Progressive | C45: Progressive Detailed Statement 06/2026 | D45: 867082146 | E45: RIVERA M. | F45: Endorsement | G45: 06/12/2026 | H45: 1.96 | I45: 1.96 | J45: 0.14 | K45: 0.27 | L45: =ROUND(I45*J45,2) -> 0.27 | M45: =K45-L45 -> 0 | N45: =IF(F45="Promotional Incentive",0,I45) -> 1.96 | O45: =IF(F45="Promotional Incentive",0,K45) -> 0.27 | P45: No
A46: Progressive|867301131 | B46: Progressive | C46: Progressive Detailed Statement 06/2026 | D46: 867301131 | E46: RICHARDS L. | F46: Renewal | G46: 06/23/2026 | H46: 476 | I46: 476 | J46: 0.1 | K46: 47.6 | L46: =ROUND(I46*J46,2) -> 47.6 | M46: =K46-L46 -> 0 | N46: =IF(F46="Promotional Incentive",0,I46) -> 476 | O46: =IF(F46="Promotional Incentive",0,K46) -> 47.6 | P46: No
A47: Progressive|867412033 | B47: Progressive | C47: Progressive Detailed Statement 06/2026 | D47: 867412033 | E47: GREEN K. | F47: Renewal | G47: 06/27/2026 | H47: 1473 | I47: 1473 | J47: 0.1 | K47: 147.3 | L47: =ROUND(I47*J47,2) -> 147.3 | M47: =K47-L47 -> 0 | N47: =IF(F47="Promotional Incentive",0,I47) -> 1473 | O47: =IF(F47="Promotional Incentive",0,K47) -> 147.3 | P47: No
... A189: Progressive|999745921 | B189: Progressive | C189: Progressive Detailed Statement 06/2026 | D189: 999745921 | E189: BLOMBERG E. | F189: Renewal | G189: 07/03/2026 | H189: 2048 | I189: 2048 | J189: 0.1 | K189: 204.8 | L189: =ROUND(I189*J189,2) -> 204.8 | M189: =K189-L189 -> 0 | N189: =IF(F189="Promotional Incentive",0,I189) -> 2048 | O189: =IF(F189="Promotional Incentive",0,K189) -> 204.8 | P189: No
A190: Infinity|10074082701 | B190: Infinity | C190: Kemper Auto Monthly Producer Stmt 06/2026 | D190: 10074082701 | E190: VERA, MANUEL | F190: Renewal | G190: 06/13/2026 | H190: 1425 | I190: 1425 | J190: 0.1 | K190: 142.5 | L190: =ROUND(I190*J190,2) -> 142.5 | M190: =K190-L190 -> 0 | N190: =IF(F190="Promotional Incentive",0,I190) -> 1425 | O190: =IF(F190="Promotional Incentive",0,K190) -> 142.5 | P190: YES | Q190: MANUEL VERA
A191: Infinity|10268755201 | B191: Infinity | C191: Kemper Auto Monthly Producer Stmt 06/2026 | D191: 10268755201 | E191: CASTILLO, MARLENE | F191: New | G191: 06/01/2026 | H191: 1183 | I191: 1183 | J191: 0.1 | K191: 118.3 | L191: =ROUND(I191*J191,2) -> 118.3 | M191: =K191-L191 -> 0 | N191: =IF(F191="Promotional Incentive",0,I191) -> 1183 | O191: =IF(F191="Promotional Incentive",0,K191) -> 118.3 | P191: YES | Q191: MARLENE CASTILLO
A192: Infinity|10268783901 | B192: Infinity | C192: Kemper Auto Monthly Producer Stmt 06/2026 | D192: 10268783901 | E192: JOHNSON, LIONEL | F192: New | G192: 06/05/2026 | H192: 934 | I192: 934 | J192: 0.1 | K192: 93.4 | L192: =ROUND(I192*J192,2) -> 93.4 | M192: =K192-L192 -> 0 | N192: =IF(F192="Promotional Incentive",0,I192) -> 934 | O192: =IF(F192="Promotional Incentive",0,K192) -> 93.4 | P192: YES | Q192: LIONEL JOHNSON
A193: Infinity|10270293001 | B193: Infinity | C193: Kemper Auto Monthly Producer Stmt 06/2026 | D193: 10270293001 | E193: PRESSLEY, TAURUS | F193: New | G193: 06/20/2026 | H193: 810 | I193: 810 | J193: 0.1 | K193: 81 | L193: =ROUND(I193*J193,2) -> 81 | M193: =K193-L193 -> 0 | N193: =IF(F193="Promotional Incentive",0,I193) -> 810 | O193: =IF(F193="Promotional Incentive",0,K193) -> 81 | P193: YES | Q193: TAURUS L. PRESSLEY
A194: Infinity|10270429601 | B194: Infinity | C194: Kemper Auto Monthly Producer Stmt 06/2026 | D194: 10270429601 | E194: GONZALEZ, FELIPE | F194: New | G194: 06/23/2026 | H194: 1450 | I194: 1450 | J194: 0.1 | K194: 145 | L194: =ROUND(I194*J194,2) -> 145 | M194: =K194-L194 -> 0 | N194: =IF(F194="Promotional Incentive",0,I194) -> 1450 | O194: =IF(F194="Promotional Incentive",0,K194) -> 145 | P194: YES | Q194: FELIPE GONZALEZ
A195: Infinity|10027857401 | B195: Infinity | C195: Kemper Auto Monthly Producer Stmt 06/2026 | D195: 10027857401 | E195: VALDES, VICTOR | F195: ENDORSE | G195: 06/08/2026 | H195: 36 | I195: 36 | J195: 0.1 | K195: 3.6 | L195: =ROUND(I195*J195,2) -> 3.6 | M195: =K195-L195 -> 0 | N195: =IF(F195="Promotional Incentive",0,I195) -> 36 | O195: =IF(F195="Promotional Incentive",0,K195) -> 3.6 | P195: No
A196: Infinity|10027857401 | B196: Infinity | C196: Kemper Auto Monthly Producer Stmt 06/2026 | D196: 10027857401 | E196: VALDES, VICTOR | F196: CnxFinal | G196: 06/26/2026 | H196: -189 | I196: -189 | J196: 0.1 | K196: -18.9 | L196: =ROUND(I196*J196,2) -> -18.9 | M196: =K196-L196 -> 0 | N196: =IF(F196="Promotional Incentive",0,I196) -> -189 | O196: =IF(F196="Promotional Incentive",0,K196) -> -18.9 | P196: No
A197: Infinity|10193915602 | B197: Infinity | C197: Kemper Auto Monthly Producer Stmt 06/2026 | D197: 10193915602 | E197: TAS, RESUL | F197: New | G197: 06/17/2026 | H197: 361 | I197: 361 | J197: 0.1 | K197: 36.1 | L197: =ROUND(I197*J197,2) -> 36.1 | M197: =K197-L197 -> 0 | N197: =IF(F197="Promotional Incentive",0,I197) -> 361 | O197: =IF(F197="Promotional Incentive",0,K197) -> 36.1 | P197: No
A198: Infinity|10213255201 | B198: Infinity | C198: Kemper Auto Monthly Producer Stmt 06/2026 | D198: 10213255201 | E198: PEREZ ROY, JUAN | F198: CnxFinal | G198: 05/23/2026 | H198: -584 | I198: -584 | J198: 0.1 | K198: -58.4 | L198: =ROUND(I198*J198,2) -> -58.4 | M198: =K198-L198 -> 0 | N198: =IF(F198="Promotional Incentive",0,I198) -> -584 | O198: =IF(F198="Promotional Incentive",0,K198) -> -58.4 | P198: No
A199: Infinity|10213255201 | B199: Infinity | C199: Kemper Auto Monthly Producer Stmt 06/2026 | D199: 10213255201 | E199: PEREZ ROY, JUAN | F199: CnxFinal | G199: 06/29/2026 | H199: -2950 | I199: -2950 | J199: 0.1 | K199: -295 | L199: =ROUND(I199*J199,2) -> -295 | M199: =K199-L199 -> 0 | N199: =IF(F199="Promotional Incentive",0,I199) -> -2950 | O199: =IF(F199="Promotional Incentive",0,K199) -> -295 | P199: No
A200: Infinity|10239866201 | B200: Infinity | C200: Kemper Auto Monthly Producer Stmt 06/2026 | D200: 10239866201 | E200: FRATER, SYLVESTER | F200: CnxFinal | G200: 06/14/2026 | H200: -460 | I200: -460 | J200: 0.1 | K200: -46 | L200: =ROUND(I200*J200,2) -> -46 | M200: =K200-L200 -> 0 | N200: =IF(F200="Promotional Incentive",0,I200) -> -460 | O200: =IF(F200="Promotional Incentive",0,K200) -> -46 | P200: No
A201: Infinity|10260538001 | B201: Infinity | C201: Kemper Auto Monthly Producer Stmt 06/2026 | D201: 10260538001 | E201: RAI, DIVYANI | F201: ENDORSE | G201: 06/20/2026 | H201: -6 | I201: -6 | J201: 0.1 | K201: -0.6 | L201: =ROUND(I201*J201,2) -> -0.6 | M201: =K201-L201 -> 0 | N201: =IF(F201="Promotional Incentive",0,I201) -> -6 | O201: =IF(F201="Promotional Incentive",0,K201) -> -0.6 | P201: No
A202: Infinity|10260538001 | B202: Infinity | C202: Kemper Auto Monthly Producer Stmt 06/2026 | D202: 10260538001 | E202: RAI, DIVYANI | F202: ENDORSE | G202: 06/20/2026 | H202: -44 | I202: -44 | J202: 0.1 | K202: -4.4 | L202: =ROUND(I202*J202,2) -> -4.4 | M202: =K202-L202 -> 0 | N202: =IF(F202="Promotional Incentive",0,I202) -> -44 | O202: =IF(F202="Promotional Incentive",0,K202) -> -4.4 | P202: No
...

Sheet Carrier Recap
A1: Recap by Carrier - Doral Binder Book vs. Full Carrier Statement
A3: Carrier | B3: Commission Statement | C3: Rate the Carrier Shows | D3: Binder Policies | E3: Found on Statement | F3: Commissionable Premium (binder clients) | G3: Commission Earned (binder clients) | H3: Total Commission on Statement (all agency business) | I3: Binder Share of Statement | J3: Other Book Activity - Txns | K3: Other Book Activity - Commission | L3: Statement Adjustments (Doral) | M3: Total Doral Commission
A4: Progressive | B4: Progressive Detailed Statement 06/2026 | C4: 8% - 14%, varies by policy | D4: 36 | E4: =SUMPRODUCT(('Commission Summary'!$F$6:$F$74=$A4)*('Commission Summary'!$L$6:$L$74>0)) -> 30 | F4: =SUMIF('Commission Summary'!$F$6:$F$74,$A4,'Commission Summary'!$N$6:$N$74) -> 42357.06 | G4: =SUMIF('Commission Summary'!$F$6:$F$74,$A4,'Commission Summary'!$O$6:$O$74) -> 4351.14 | H4: =SUMIF('Transaction Detail'!$B$2:$B$385,$A4,'Transaction Detail'!$K$2:$K$385) -> 14289.02 | I4: =IF(H4=0,"",G4/H4) -> 0.30450934 | J4: 25 | K4: ='Book Activity by Carrier'!J31 -> 64.35 | L4: =SUMIFS('Book Activity by Carrier'!$F$135:$F$162,'Book Activity by Carrier'!$C$135:$C$162,"Progressive",'Book Activity by Carrier'!$J$135:$J$162,"YES") -> 0 | M4: =G4+K4+L4 -> 4415.49
A5: Infinity | B5: Kemper Auto Monthly Producer Stmt 06/2026 | C5: 10% flat | D5: 9 | E5: =SUMPRODUCT(('Commission Summary'!$F$6:$F$74=$A5)*('Commission Summary'!$L$6:$L$74>0)) -> 5 | F5: =SUMIF('Commission Summary'!$F$6:$F$74,$A5,'Commission Summary'!$N$6:$N$74) -> 5802 | G5: =SUMIF('Commission Summary'!$F$6:$F$74,$A5,'Commission Summary'!$O$6:$O$74) -> 580.2 | H5: =SUMIF('Transaction Detail'!$B$2:$B$385,$A5,'Transaction Detail'!$K$2:$K$385) -> 656.6 | I5: =IF(H5=0,"",G5/H5) -> 0.88364301 | J5: 8 | K5: ='Book Activity by Carrier'!J42 -> -692.6 | L5: =SUMIFS('Book Activity by Carrier'!$F$135:$F$162,'Book Activity by Carrier'!$C$135:$C$162,"Infinity",'Book Activity by Carrier'!$J$135:$J$162,"YES") -> 0 | M5: =G5+K5+L5 -> -112.4
A6: United Auto | B6: United Insurance Group Direct Billing Stmt 06/2026 | C6: 10% as collected (3% incentive excluded) | D6: 10 | E6: =SUMPRODUCT(('Commission Summary'!$F$6:$F$74=$A6)*('Commission Summary'!$L$6:$L$74>0)) -> 10 | F6: =SUMIF('Commission Summary'!$F$6:$F$74,$A6,'Commission Summary'!$N$6:$N$74) -> 9025.3 | G6: =SUMIF('Commission Summary'!$F$6:$F$74,$A6,'Commission Summary'!$O$6:$O$74) -> 902.53 | H6: =SUMIF('Transaction Detail'!$B$2:$B$385,$A6,'Transaction Detail'!$K$2:$K$385) -> 444.33 | I6: =IF(H6=0,"",G6/H6) -> 2.0312155 | J6: 58 | K6: ='Book Activity by Carrier'!J103 -> -657.67 | L6: =SUMIFS('Book Activity by Carrier'!$F$135:$F$162,'Book Activity by Carrier'!$C$135:$C$162,"United Auto",'Book Activity by Carrier'!$J$135:$J$162,"YES") -> 0 | M6: =G6+K6+L6 -> 244.86
A7: Ocean Harbor | B7: Pearl Holding Group Commission Stmt 06/2026 | C7: 11% (13% on some policies) | D7: 2 | E7: =SUMPRODUCT(('Commission Summary'!$F$6:$F$74=$A7)*('Commission Summary'!$L$6:$L$74>0)) -> 2 | F7: =SUMIF('Commission Summary'!$F$6:$F$74,$A7,'Commission Summary'!$N$6:$N$74) -> 2294 | G7: =SUMIF('Commission Summary'!$F$6:$F$74,$A7,'Commission Summary'!$O$6:$O$74) -> 252.34 | H7: =SUMIF('Transaction Detail'!$B$2:$B$385,$A7,'Transaction Detail'!$K$2:$K$385) -> 326.21 | I7: =IF(H7=0,"",G7/H7) -> 0.77355078 | J7: 2 | K7: ='Book Activity by Carrier'!J108 -> -60.11 | L7: =SUMIFS('Book Activity by Carrier'!$F$135:$F$162,'Book Activity by Carrier'!$C$135:$C$162,"Ocean Harbor",'Book Activity by Carrier'!$J$135:$J$162,"YES") -> -8.36 | M7: =G7+K7+L7 -> 183.87
A8: National General | B8: National General Commission Stmt 06/2026 | C8: 10% flat | D8: 3 | E8: =SUMPRODUCT(('Commission Summary'!$F$6:$F$74=$A8)*('Commission Summary'!$L$6:$L$74>0)) -> 2 | F8: =SUMIF('Commission Summary'!$F$6:$F$74,$A8,'Commission Summary'!$N$6:$N$74) -> 2334 | G8: =SUMIF('Commission Summary'!$F$6:$F$74,$A8,'Commission Summary'!$O$6:$O$74) -> 233.4 | H8: =SUMIF('Transaction Detail'!$B$2:$B$385,$A8,'Transaction Detail'!$K$2:$K$385) -> 871.27 | I8: =IF(H8=0,"",G8/H8) -> 0.26788481 | J8: 7 | K8: ='Book Activity by Carrier'!J118 -> -202.23 | L8: =SUMIFS('Book Activity by Carrier'!$F$135:$F$162,'Book Activity by Carrier'!$C$135:$C$162,"National General",'Book Activity by Carrier'!$J$135:$J$162,"YES") -> -35.06 | M8: =G8+K8+L8 -> -3.89
A9: AmWins | B9: Amwins Specialty Auto Commission Stmt 06/2026 | C9: 10% of net cash | D9: 3 | E9: =SUMPRODUCT(('Commission Summary'!$F$6:$F$74=$A9)*('Commission Summary'!$L$6:$L$74>0)) -> 3 | F9: =SUMIF('Commission Summary'!$F$6:$F$74,$A9,'Commission Summary'!$N$6:$N$74) -> 420.67 | G9: =SUMIF('Commission Summary'!$F$6:$F$74,$A9,'Commission Summary'!$O$6:$O$74) -> 42.07 | H9: =SUMIF('Transaction Detail'!$B$2:$B$385,$A9,'Transaction Detail'!$K$2:$K$385) -> 72.34 | I9: =IF(H9=0,"",G9/H9) -> 0.5815593 | J9: 1 | K9: ='Book Activity by Carrier'!J122 -> 0.07 | L9: =SUMIFS('Book Activity by Carrier'!$F$135:$F$162,'Book Activity by Carrier'!$C$135:$C$162,"AmWins",'Book Activity by Carrier'!$J$135:$J$162,"YES") -> 0 | M9: =G9+K9+L9 -> 42.14
A10: GEICO | B10: GEICO Commission Statement 06/2026 | C10: 10% / 12% / 15% | D10: 0 | E10: 0 | F10: 0 | G10: 0 | H10: =SUMIF('Transaction Detail'!$B$2:$B$385,$A10,'Transaction Detail'!$K$2:$K$385) -> 2267.79 | J10: 2 | K10: ='Book Activity by Carrier'!J127 -> -45.78 | L10: =SUMIFS('Book Activity by Carrier'!$F$135:$F$162,'Book Activity by Carrier'!$C$135:$C$162,"GEICO",'Book Activity by Carrier'!$J$135:$J$162,"YES") -> 0 | M10: =G10+K10+L10 -> -45.78
A11: TOTAL | D11: =SUM(D4:D10) -> 63 | E11: =SUM(E4:E10) -> 52 | F11: =SUM(F4:F10) -> 62233.03 | G11: =SUM(G4:G10) -> 6361.68 | H11: =SUM(H4:H10) -> 18927.56 | I11: =IF(H11=0,"",G11/H11) -> 0.33610671 | J11: =SUM(J4:J10) -> 103 | K11: =SUM(K4:K10) -> -1593.97 | L11: =SUM(L4:L10) -> -43.42 | M11: =SUM(M4:M10) -> 4724.29

Sheet Book Activity by Carrier
A1: Other Doral Book Activity on the June 2026 Carrier Statements
A2: Transactions belonging to the wider Doral office book of business that appear on the June carrier statements but are NOT on the June binder sheet - endorsements, cancellations, adjustments and as-collected commission on policies written in earlier months.
A4: Customer Name (per Doral book) | B4: Policy Number | C4: Insured Name (per statement) | D4: Transaction Type | E4: Transaction Date | F4: Premium / Basis | G4: Premium Counted | H4: Carrier Comm Rate | I4: Commission per Statement | J4: Commission Counted | K4: Book Month | L4: Company (per book)
A5: PROGRESSIVE - 25 transactions
A6: IVAN D MOLINA LOZANO | B6: 862085078 | C6: MOLINA LOZAN I. | D6: Endorsement | E6: 06/06/2026 | F6: 299.97 | G6: =IF(D6="Promotional Incentive",0,F6) -> 299.97 | H6: 0.1 | I6: 30 | J6: =IF(D6="Promotional Incentive",0,I6) -> 30 | K6: FEB 26 | L6: Progressive
A7: GUILLERMO FAYAS RODRIGUEZ | B7: 867943703 | C7: FAYAS RODRIG G. | D7: Renewal | E7: 07/08/2026 | F7: 1794 | G7: =IF(D7="Promotional Incentive",0,F7) -> 1794 | H7: 0.1 | I7: 179.4 | J7: =IF(D7="Promotional Incentive",0,I7) -> 179.4 | K7: JULY 26 | L7: Progressive
A8: KATHERINE A FERNANDEZ | B8: 869341373 | C8: FERNANDEZ K. | D8: Cancel Pro Rate | E8: 06/05/2026 | F8: -592.29 | G8: =IF(D8="Promotional Incentive",0,F8) -> -592.29 | H8: 0.1 | I8: -59.23 | J8: =IF(D8="Promotional Incentive",0,I8) -> -59.23 | K8: FEB 26 | L8: Progressive
A9: IVAN S FLORES JARAMILLO | B9: 869745230 | C9: FLORES JARAM I. | D9: Endorsement | E9: 06/10/2026 | F9: 0 | G9: =IF(D9="Promotional Incentive",0,F9) -> 0 | H9: 0.1 | I9: 0 | J9: =IF(D9="Promotional Incentive",0,I9) -> 0 | K9: FEB 26 | L9: Progressive
A10: CAROL J SAFI | B10: 871135598 | C10: SAFI C. | D10: Credit Endorsement | E10: 06/09/2026 | F10: -133.12 | G10: =IF(D10="Promotional Incentive",0,F10) -> -133.12 | H10: 0.1 | I10: -13.31 | J10: =IF(D10="Promotional Incentive",0,I10) -> -13.31 | K10: data march | L10: Progressive
A11: JUAN J ORTUNO | B11: 871466655 | C11: ORTUNO J. | D11: Credit Endorsement | E11: 06/12/2026 | F11: -26.08 | G11: =IF(D11="Promotional Incentive",0,F11) -> -26.08 | H11: 0.1 | I11: -2.61 | J11: =IF(D11="Promotional Incentive",0,I11) -> -2.61 | K11: data march | L11: Progressive
A12: DAVID GUERRA | B12: 872036378 | C12: GUERRA D. | D12: Cancel Pro Rate | E12: 06/29/2026 | F12: -736.55 | G12: =IF(D12="Promotional Incentive",0,F12) -> -736.55 | H12: 0.12 | I12: -88.39 | J12: =IF(D12="Promotional Incentive",0,I12) -> -88.39 | K12: data april | L12: Progressive
A13: PAULINA GUERRERO | B13: 872333790 | C13: GUERRERO P. | D13: Cancel Pro Rate | E13: 06/29/2026 | F13: -579.3 | G13: =IF(D13="Promotional Incentive",0,F13) -> -579.3 | H13: 0.1 | I13: -57.93 | J13: =IF(D13="Promotional Incentive",0,I13) -> -57.93 | K13: data april | L13: Progressive
A14: JOSE MICO I. | B14: 872526456 | C14: MICO IZQUIER J. | D14: Endorsement | E14: 06/09/2026 | F14: 100.14 | G14: =IF(D14="Promotional Incentive",0,F14) -> 100.14 | H14: 0.1 | I14: 10.01 | J14: =IF(D14="Promotional Incentive",0,I14) -> 10.01 | K14: data april | L14: Progressive
A15: JOSE MICO I. | B15: 872526456 | C15: MICO IZQUIER J. | D15: Cancel Pro Rate | E15: 07/01/2026 | F15: -1413.68 | G15: =IF(D15="Promotional Incentive",0,F15) -> -1413.68 | H15: 0.1 | I15: -141.37 | J15: =IF(D15="Promotional Incentive",0,I15) -> -141.37 | K15: data april | L15: Progressive
A16: ROSS M LAZAREK | B16: 873197162 | C16: LAZAREK R. | D16: Credit Endorsement | E16: 06/15/2026 | F16: -33.64 | G16: =IF(D16="Promotional Incentive",0,F16) -> -33.64 | H16: 0.14 | I16: -4.71 | J16: =IF(D16="Promotional Incentive",0,I16) -> -4.71 | K16: data april | L16: Progressive
A17: JOSE DIAZ | B17: 874616317 | C17: DIAZ J. | D17: Cancel Pro Rate | E17: 05/27/2026 | F17: -744.72 | G17: =IF(D17="Promotional Incentive",0,F17) -> -744.72 | H17: 0.1 | I17: -74.47 | J17: =IF(D17="Promotional Incentive",0,I17) -> -74.47 | K17: data may | L17: Progressive
... A30: EMILEY BLOMBERG | B30: 999745921 | C30: BLOMBERG E. | D30: Renewal | E30: 07/03/2026 | F30: 2048 | G30: =IF(D30="Promotional Incentive",0,F30) -> 2048 | H30: 0.1 | I30: 204.8 | J30: =IF(D30="Promotional Incentive",0,I30) -> 204.8 | K30: JULY 26 | L30: Progressive
A31: Progressive subtotal | F31: =SUM(F6:F30) -> 558.91 | G31: =SUM(G6:G30) -> 558.91 | I31: =SUM(I6:I30) -> 64.35 | J31: =SUM(J6:J30) -> 64.35
A33: INFINITY - 8 transactions
A34: RESUL TAS | B34: 10193915602 | C34: TAS, RESUL | D34: New | E34: 06/17/2026 | F34: 361 | G34: =IF(D34="Promotional Incentive",0,F34) -> 361 | H34: 0.1 | I34: 36.1 | J34: =IF(D34="Promotional Incentive",0,I34) -> 36.1 | K34: FEB 25 | L34: Infinity
A35: JUAN PEREZ ROY | B35: 10213255201 | C35: PEREZ ROY, JUAN | D35: CnxFinal | E35: 05/23/2026 | F35: -584 | G35: =IF(D35="Promotional Incentive",0,F35) -> -584 | H35: 0.1 | I35: -58.4 | J35: =IF(D35="Promotional Incentive",0,I35) -> -58.4 | K35: JULIO 25 | L35: Infinity
A36: JUAN PEREZ ROY | B36: 10213255201 | C36: PEREZ ROY, JUAN | D36: CnxFinal | E36: 06/29/2026 | F36: -2950 | G36: =IF(D36="Promotional Incentive",0,F36) -> -2950 | H36: 0.1 | I36: -295 | J36: =IF(D36="Promotional Incentive",0,I36) -> -295 | K36: JULIO 25 | L36: Infinity
A37: SYLVESTER FRATER | B37: 10239866201 | C37: FRATER, SYLVESTER | D37: CnxFinal | E37: 06/14/2026 | F37: -460 | G37: =IF(D37="Promotional Incentive",0,F37) -> -460 | H37: 0.1 | I37: -46 | J37: =IF(D37="Promotional Incentive",0,I37) -> -46 | K37: JULIO 25 | L37: Infinity
A38: DIVYANI RAI | B38: 10260538001 | C38: RAI, DIVYANI | D38: ENDORSE | E38: 06/20/2026 | F38: -6 | G38: =IF(D38="Promotional Incentive",0,F38) -> -6 | H38: 0.1 | I38: -0.6 | J38: =IF(D38="Promotional Incentive",0,I38) -> -0.6 | K38: data march | L38: Infinity
A39: DIVYANI RAI | B39: 10260538001 | C39: RAI, DIVYANI | D39: ENDORSE | E39: 06/20/2026 | F39: -44 | G39: =IF(D39="Promotional Incentive",0,F39) -> -44 | H39: 0.1 | I39: -4.4 | J39: =IF(D39="Promotional Incentive",0,I39) -> -4.4 | K39: data march | L39: Infinity
A40: JABIERQUIS MENDOZA | B40: 10260713001 | C40: MENDOZA, JABIERQUIS | D40: CnxFinal | E40: 06/03/2026 | F40: -698 | G40: =IF(D40="Promotional Incentive",0,F40) -> -698 | H40: 0.1 | I40: -69.8 | J40: =IF(D40="Promotional Incentive",0,I40) -> -69.8 | K40: data march | L40: Infinity
A41: JORGE O RIVAS (STREN DISTRIBUTOR) | B41: 50026396402 | C41: RIVAS, JORGE | D41: CnxFinal | E41: 06/24/2026 | F41: -2545 | G41: =IF(D41="Promotional Incentive",0,F41) -> -2545 | H41: 0.1 | I41: -254.5 | J41: =IF(D41="Promotional Incentive",0,I41) -> -254.5 | K41: FEB 26 | L41: Infinity
A42: Infinity subtotal | F42: =SUM(F34:F41) -> -6926 | G42: =SUM(G34:G41) -> -6926 | I42: =SUM(I34:I41) -> -692.6 | J42: =SUM(J34:J41) -> -692.6
A44: UNITED AUTO - 58 transactions
A45: VICTOR GARCIA BARRERAS | B45: UAD 602082206 | C45: VICTOR E GARCIA BARRE | D45: Comm as Collected | E45: 06/30/26 | F45: 269.1 | G45: =IF(D45="Promotional Incentive",0,F45) -> 269.1 | H45: 0.1 | I45: 26.91 | J45: =IF(D45="Promotional Incentive",0,I45) -> 26.91 | K45: FEB 26 | L45: United Auto
A46: TIMMIE ROZIER | B46: UAD 606159902 | C46: TIMMIE ROZIER | D46: Comm as Collected | E46: 06/30/26 | F46: 178.9 | G46: =IF(D46="Promotional Incentive",0,F46) -> 178.9 | H46: 0.1 | I46: 17.89 | J46: =IF(D46="Promotional Incentive",0,I46) -> 17.89 | K46: JULY 26 | L46: United Auto
A47: BIANCA R. BUZZIZ | B47: UAD 606715305 | C47: BIANCA R BUZZIZ | D47: Comm as Collected | E47: 06/30/26 | F47: 212.9 | G47: =IF(D47="Promotional Incentive",0,F47) -> 212.9 | H47: 0.1 | I47: 21.29 | J47: =IF(D47="Promotional Incentive",0,I47) -> 21.29 | K47: FEB 26 | L47: United Auto
A48: ORESTE CANIZARES GONZALEZ | B48: UAD 607888404 | C48: ORESTE CANIZARES GONZ | D48: Comm as Collected | E48: 06/30/26 | F48: 202.2 | G48: =IF(D48="Promotional Incentive",0,F48) -> 202.2 | H48: 0.1 | I48: 20.22 | J48: =IF(D48="Promotional Incentive",0,I48) -> 20.22 | K48: data may | L48: United Auto
A49: ORESTE CANIZARES GONZALEZ | B49: UAD 607888404 | C49: ORESTE CANIZARES GONZ | D49: Promotional Incentive | E49: 06/30/26 | F49: 202.2 | G49: =IF(D49="Promotional Incentive",0,F49) -> 0 | H49: 0.03 | I49: 6.06 | J49: =IF(D49="Promotional Incentive",0,I49) -> 0 | K49: data may | L49: United Auto
A50: JOSE ANTONIO CRUZ PEREZ | B50: UAE 000217449 | C50: JOSE A CRUZ PEREZ | D50: Comm as Collected | E50: 06/30/26 | F50: 420.7 | G50: =IF(D50="Promotional Incentive",0,F50) -> 420.7 | H50: 0.1 | I50: 42.07 | J50: =IF(D50="Promotional Incentive",0,I50) -> 42.07 | K50: JULIO 25 | L50: United Auto
A51: JUAN J PAYANO | B51: UAE 000225427 | C51: JUAN J PAYANO | D51: Comm as Collected | E51: 06/30/26 | F51: 190.6 | G51: =IF(D51="Promotional Incentive",0,F51) -> 190.6 | H51: 0.1 | I51: 19.06 | J51: =IF(D51="Promotional Incentive",0,I51) -> 19.06 | K51: JULIO 25 | L51: United Auto
A52: LUIS MARIO ORTUNO | B52: UAE 000254009 | C52: LUIS M ORTUNO | D52: Comm as Collected | E52: 06/30/26 | F52: 94.4 | G52: =IF(D52="Promotional Incentive",0,F52) -> 94.4 | H52: 0.1 | I52: 9.44 | J52: =IF(D52="Promotional Incentive",0,I52) -> 9.44 | K52: NOV 25 | L52: United Auto
A53: KENOLD MERVEILLE | B53: UAE 000268427 | C53: KENOLD MERVEILLE | D53: Endorsement | E53: 06/28/26 | F53: 0 | G53: =IF(D53="Promotional Incentive",0,F53) -> 0 | H53: 0.1 | I53: 0 | J53: =IF(D53="Promotional Incentive",0,I53) -> 0 | K53: data march | L53: United Auto
A54: KENOLD MERVEILLE | B54: UAE 000268427 | C54: KENOLD MERVEILLE | D54: Promotional Incentive | E54: 06/28/26 | F54: 0 | G54: =IF(D54="Promotional Incentive",0,F54) -> 0 | H54: 0.03 | I54: 0 | J54: =IF(D54="Promotional Incentive",0,I54) -> 0 | K54: data march | L54: United Auto
A55: MIRLOUDE PETIT FRERE | B55: UAH 000518008 | C55: MIRLOUDE PETIT FRERE | D55: Cancel (Prorate) | E55: 06/16/26 | F55: -2598 | G55: =IF(D55="Promotional Incentive",0,F55) -> -2598 | H55: 0.1 | I55: -259.8 | J55: =IF(D55="Promotional Incentive",0,I55) -> -259.8 | K55: data april | L55: United Auto
...

Sheet Notes & Sources
A1: Notes, Sources & Methodology
A3: Source files
A4: June binder sheet | B4: Doral_Office_Binder_Book_June_Sheet.pdf - 63 policies (18 new business, 45 renewals), producer Jorge. This drives the Commission Summary tab.
A5: Full book of business | B5: Doral_Office_Binder_Book.xlsx - the whole Doral office book, 54 monthly sheets from Dec 2022 to Aug 2026, 2,706 policy rows and 1,383 distinct policy numbers. This drives the Book Activity by Carrier tab.
A6: Progressive | B6: DetailedStatement20260811_Progressive.xlsx - 188 transactions, agent 24258, month end 202606. Ties to the Summary tab of that file: $14,289.02.
A7: Infinity | B7: Kemper.pdf - Kemper Auto Monthly Producer Statement, agent 5517897. 27 transactions, ties to the FL Commission Total: $656.60.
A8: United Auto | B8: United_100208_June_statement.PDF - United Insurance Group, agent 001-1D-100208, premium period 06/01/26-06/30/26. 98 transactions netting $444.33, which ties to the statement current balance.
A9: Ocean Harbor | B9: Pearl_Holding_Statement.pdf - Pearl Holding Group, producer code 6883. 6 transactions, ties to Commission Due: $326.21.
A10: National General | B10: National_General_Commission_Statement_DB_June_2026.xlsx - Princeton code 9019644. 18 transactions, ties to Grand Total Commission: $871.27.
A11: AmWins | B11: Amwins_Comm_1.PDF - Amwins Specialty Auto of Florida, agent 246500. 9 rows, ties to the Agency Total: $72.34.
A12: GEICO | B12: Commission_Statement_35.pdf - GEICO, payee Universal Brokers LLC. 38 transactions, ties to the Payment Amount: $2,267.79.
A14: How commission is calculated
A15: Matching | B15: Every binder-book policy was matched to the carrier statements by POLICY NUMBER, not by name, so name spelling differences between the binder and the carriers do not affect the result.
A16: Rate used | B16: The rate is taken from the carrier statement itself - it is never assumed. Column K of the Transaction Detail tab is the commission the carrier printed; column L re-performs it as basis x rate and column M shows any difference.
A17: Progressive basis | B17: Gross premium on the Progressive detail line. Progressive shows a per-policy rate that varies: 8%, 9%, 10%, 12% and 14% all appear.
A18: Infinity basis | B18: Premium column on the Kemper statement. Kemper shows a flat 0.10 (10%) on every FL line.
A19: United Auto basis | B19: Transaction amount on the United statement, booked at 10% AS COLLECTED.
A20: United Auto 3% incentive | B20: United also pays a separate 3% PROMOTIONAL INCENTIVE line on most policies. By instruction this workbook books United at 10% only, so those incentive lines are EXCLUDED from every Doral total. They are still carried on the Transaction Detail tab exactly as United shows them (column K, shaded), and column O zeroes them so they never reach the Commission Summary. The amount excluded for Doral clients is $252.85 - if you later decide to book it, that is what it would add.
A21: United Auto as collected | B21: Most United policies are direct bill and pay COMM AS COLLECTED, meaning June commission is earned only on the premium United actually collected in June - not on the full term premium. That is why, for example, Luis A. Ortiz shows $163.60 commissionable against a $1,103.35 binder premium. The rest of that policy will earn commission on later monthly statements. The four United new-business policies (Gustave, Cordero, Vazquez, Howard) are shown on full premium.
A22: United Auto net | B22: United's statement nets to $444.33 for the whole agency because cancellations on non-Doral policies charge back more than $1,300. The Doral book on its own earned $902.53 at 10%, which is why its share of that statement reads over 100% on the Carrier Recap tab.
A23: United Auto signs | B23: United prints amounts owed TO the agency with a trailing minus and chargebacks as positives. Those signs are reversed in this workbook so that commission earned is positive and chargebacks are negative, which is why the sum here reads $444.33 rather than $444.33-.
A24: Ocean Harbor basis | B24: Premium only. The $35.00 policy fee that Pearl lists separately is NOT commissionable - e.g. Javier Forero: $1,153.00 x 11% = $126.83, with the $35.00 fee excluded. The binder premium of $1,188.00 is premium plus fee, which is why it is higher than the commissionable premium.
A25: National General basis | B25: Written premium on the Summary Details tab. National General shows a flat 10%.
A26: AmWins basis | B26: NET CASH (gross cash less fees), not written premium. AmWins shows 10% and applies it to net cash - e.g. Angely Gejo: $164.67 net cash x 10% = $16.47.
... A28: Multiple transactions | B28: Where a policy has more than one line in the month, all lines are netted and the Notes column on the summary lists them. United incentive lines repeat the same premium as their 10% line, so they are excluded from Commissionable Premium as well (column N of the detail tab) and the premium is never double counted.
A30: Items with no June commission
A31: Not on the June statement | B31: 6 Progressive renewals on the binder book do not appear anywhere in the June Progressive detail: Amarillys Gonzalez (970306264), Brudys Garcia (990100610), Yosvany Larralde (982064065), Ana G Castano (866496112), Manuel Martinez (990228513), Reysel Castillo (970570633). Verified by both policy number and name. Most likely the commission fell into the May or July statement period - worth following up with Progressive.
A32: No June activity | B32: 5 policies are 12-month contracts effective in late 2025 that carry no premium on the binder sheet and show no June 2026 activity on their carrier statement, so $0 is the correct answer for them this month, not a missing match: Levy Diaz Torres, Elizabeth Mirabal Hernandez, Ana Maria Acosta and James John Ciullo (all Infinity), plus Armando Caralos (National General, policy 2032597919).
A33: GEICO | B33: No client on the June binder sheet appears on the GEICO statement, but the wider Doral book does: Iris Lopez Sanchez (policy 6219586788) has two renewal-year lines, netting -$45.78. Those two are on the Book Activity by Carrier tab. The remaining 36 GEICO transactions belong to writing agents Alberto Manzor Jr and Amanda Montano and contribute $0 to the Doral totals.
A35: Book Activity by Carrier tab
A36: What it is | B36: Every transaction on the June carrier statements that belongs to a policy in the wider Doral book of business but is NOT on the June binder sheet: endorsements, cancellations, credit endorsements, uncollected premium and as-collected commission on policies written in earlier months. Grouped into a section per carrier, each with its own subtotal.
A37: How it was matched | B37: All 384 statement transactions were tested against all 1,383 distinct policy numbers in the full book. Matching is by policy number, allowing for the suffixes carriers append (National General adds a two-digit term, GEICO appends a second number after a dash, United pads with leading zeros). Every match was then cross-checked on surname between the statement insured and the book customer - all 171 matches agreed, and none had to be resolved by judgement.
